Workbook
Name Abs_Balance: [1]Data!$V$1:$V$5000
Name ABS_PL: [1]Data!$AD$1:$AD$5000
Name ABS_PL_30: [1]Data!$AG$1:$AG$5000
Name Asset_Liab: [1]Data!$W$1:$W$5000
Name ATF: '[2]Lookup - Tables_LM'!$B$8:$B$13
Name Bal_to_Conf: [1]Data!$D$1:$D$5000
Name BOS: [3]Notes!$B$34:$C$54
Name BOS_List: [3]Notes!$B$35:$B$52
Name CONF: [1]Data!$K$1:$K$5000
Name Contingent: '[2]Adj Factors'!$B$106:$B$108
Name Countries: 'Country List'!$A$2:$A$160
Name Cr_Recon: [1]Data!$AB$1:$AB$5000
Name Data_2: '[4]CH6 Data'!$A$1:$P$51
Name Data_2: '[5]CH6 Data'!$A$1:$P$51
Name Date: [1]Inputs!$C$3
Name Debt_2: '[2]Adj Factors'!$D$83:$D$85
Name Debt_LM: '[2]Adj Factors'!$B$112:$B$114
Name Dr_Recon: [1]Data!$AA$1:$AA$5000
Name GDP_1: '[2]Adj Factors'!$B$55:$B$57
Name GDP_2: '[2]Adj Factors'!$B$60:$B$61
Name GDP_3: '[2]Adj Factors'!$B$64:$B$66
Name GDP_5: '[2]Adj Factors'!$B$73:$B$74
Name GDP_6: '[2]Adj Factors'!$B$77:$B$79
Name GetChart: IF([4]CH7!$B$7=1,INDIRECT("CH7!$B$14"),INDIRECT("CH7!$B$19"))
Name GetChart: IF([5]CH7!$B$7=1,INDIRECT("CH7!$B$14"),INDIRECT("CH7!$B$19"))
Name Getdata: IF([4]CH7!$E$7="Sales",INDIRECT("Source!$C$26"),IF([6]Example!$B$6="COS",INDIRECT("Source!$C$27"),INDIRECT("Source!$C$28")))
Name Getdata: IF([5]CH7!$E$7="Sales",INDIRECT("Source!$C$26"),IF([6]Example!$B$6="COS",INDIRECT("Source!$C$27"),INDIRECT("Source!$C$28")))
Name Green_2: [4]CH6!$G$24
Name Green_2: [5]CH6!$G$24
Name H_Expenses2: [4]CH5!#REF!
Name H_Expenses2: [5]CH5!#REF!
Name HIGH: 'Country List'!$G$2:$G$79
Name KPI_List: [4]Inputs!$J$8:$J$12
Name KPI_List: [5]Inputs!$J$8:$J$12
Name KPI_Name: [4]Inputs!$J$8:$K$11
Name KPI_Name: [5]Inputs!$J$8:$K$11
Name LOW: 'Country List'!$F$2:$F$49
Name Min_2: [4]CH6!$F$20
Name Min_2: [5]CH6!$F$20
Name No_Recon: [1]Data!$AC$1:$AC$5000
Name No_SARS: [1]Data!$U$1:$U$5000
Name Nodata: 'Country List'!$H$2:$H$35
Name Non_submission: [1]Data!$Z$1:$Z$5000
Name Period: [4]Data!$A$1:$A$141
Name Period: [5]Data!$A$1:$A$141
Name Period_List: [4]Inputs!$H$8:$H$20
Name Period_List: [5]Inputs!$H$8:$H$20
Name Period_List2: [4]Inputs!$H$9:$H$20
Name Period_List2: [5]Inputs!$H$9:$H$20
Name PL_CR: [1]Data!$AE$1:$AE$5000
Name PL_CR_30: [1]Data!$AH$1:$AH$5000
Name PL_DR: [1]Data!$AF$1:$AF$5000
Name PL_DR_30: [1]Data!$AI$1:$AI$5000
Name Position_Range: [4]Inputs!$B$8:$B$15
Name Position_Range: [5]Inputs!$B$8:$B$15
Name PRE: '[2]Lookup - Tables_LM'!$B$16:$B$22
Name Prod: [4]CH7!$F$28:$F$32
Name Prod: [5]CH7!$F$28:$F$32
Name Prod_List: [4]Inputs!$F$8:$F$12
Name Prod_List: [5]Inputs!$F$8:$F$12

Sheet Home
C8: Country Model
B9: Select Country and then the applicable Segment | G9: Select Segment directly
B10: Countries | F10: OR | G10: Country Segments
B12: SOUTH AFRICA | G12: • | H12: High Segment Country Model
G13: • | H13: Low Segment Country Model
B14: • | C14: =IF(ISNUMBER(MATCH(B12,'Country List'!F2:F49,0)),HYPERLINK("#'Low Segment'!A1","Low Segment Country Model"),IF(ISNUMBER(MATCH(B12,'Country List'!G2:G79,0)),HYPERLINK("#'High Segment'!A1","High Segment Country Model"),HYPERLINK("#'No Data Segment'!A1","No Data Model"))) -> Low Segment Country Model | G14: • | H14: No Data Model

Sheet High Segment
I1: Low mapping
I2: Economic | J2: Currency | K2: Finance | L2: Political | M2: Bus Risk | N2: Risk | O2: Overall
I3: 0 | J3: 0 | K3: 0 | L3: 0 | M3: 0 | N3: 0 | O3: 0 | P3: Very Low Risk
B4: HIGH HUMAN DEVELOPMENT | I4: 20 | J4: 20 | K4: 20 | L4: 20 | M4: 20 | N4: 20 | O4: 20 | P4: Low Risk
I5: 40 | J5: 40 | K5: 40 | L5: 40 | M5: 40 | N5: 40 | O5: 40 | P5: Moderate Risk
B6: Country Name | D6: UNITED STATES | I6: 60 | J6: 60 | K6: 60 | L6: 60 | M6: 60 | N6: 60 | O6: 60 | P6: High Risk
B7: ISO Code | D7: =VLOOKUP(D6,'Country List'!$A:$D,2,FALSE) -> USA | I7: 80 | J7: 80 | K7: 80 | L7: 80 | M7: 80 | N7: 80 | O7: 80 | P7: Very High Risk
B8: HDI Segmentation | D8: =VLOOKUP(D7,'Country List'!$B:$D,2,FALSE) -> VERY HIGH HUMAN DEVELOPMENT | I8: 100 | J8: 100 | K8: 100 | L8: 100 | M8: 100 | N8: 100 | O8: 100 | P8: Default
B9: Region | D9: =VLOOKUP(D7,'Country List'!$B:$D,3,FALSE) -> DEVELOPED MARKET | I9: Model Drivers
I10: Inflation 5 year average | J10: dcpi_5_adj | K10: 0.36915 | L10: 0.17699423 | M10: =0.5*L10 -> 0.088497113 | N10: =SUM(M10:M14) -> 0.35360935 | O10: =SUM(N10:N18) -> 0.5
I11: Nominal Interest Rate Volatility | J11: nom_rir_vol | K11: 0.30992 | L11: 0.031468549 | M11: =0.5*L11 -> 0.015734274
I12: GDP per Capita | J12: GDP_CAPITA | K12: 0.48583 | L12: 0.29341459 | M12: =0.5*L12 -> 0.1467073
I13: Growth Volatility | J13: growth_vol | K13: 0.21098 | L13: 0.043085309 | M13: =0.5*L13 -> 0.021542654
I14: Macroeconomic | J14: macro_var | K14: 0.30523 | L14: 0.16225603 | M14: =0.5*L14 -> 0.081128016
I15: Access to Finance | J15: atf | K15: 0.16803 | L15: 0.060577427 | M15: =0.5*L15 -> 0.030288713 | N15: =SUM(M15:M17) -> 0.11080833
I16: Debt Trend | J16: DT | K16: 0.31148 | L16: 0.054668955 | M16: =0.5*L16 -> 0.027334477
I17: Foreign Debt to GDP 3 year average | J17: FDG_3yr | K17: 0.2757 | L17: 0.10637028 | M17: =0.5*L17 -> 0.05318514
I18: Cost of Funds | J18: cof | K18: 0.17338 | L18: 0.07116463 | M18: =0.5*L18 -> 0.035582315 | N18: =M18 -> 0.035582315
I19: Political Risk Environment | J19: pr | K19: 0.31528 | L19: 0.27089516 | M19: =0.5*L19 -> 0.13544758 | N19: =M19 -> 0.13544758 | O19: =SUM(N19:N22) -> 0.5
I20: Rule of Law | J20: rol | K20: 0.4947 | L20: 0.45860746 | M20: =0.5*L20 -> 0.22930373 | N20: =SUM(M20:M21) -> 0.29387428
I21: Doing Business | J21: db | K21: 0.17546 | L21: 0.12914111 | M21: =0.5*L21 -> 0.064570554
I22: Security Risk | J22: sr | K22: 0.18997 | L22: 0.14135627 | M22: =0.5*L22 -> 0.070678136 | N22: =M22 -> 0.070678136
I23: Quant | J23: yhat_Quant | K23: 0.33531 | L23: 0.29206231 | M23: 0.2921443 | N23: 0.29206231 | O23: =SUM(N23:N24) -> 1
I24: Qual | J24: yhat_qual | K24: 0.74942 | L24: 0.70793769 | M24: 0.7078557 | N24: 0.70793769
I25: Quant | J25: yhat_Quant | K25: 0.54747 | L25: 0.50000345 | M25: 0.50000345 | N25: =M25 -> 0.50000345 | O25: =SUM(N25:N26) -> 1
I26: Qual | J26: yhat_qual_ridge | K26: 0.54011 | L26: 0.49999655 | M26: 0.49999655 | N26: =M26 -> 0.49999655
J27: Intercept Quant | K27: 0.78489
J28: Intercept Qual_Ridge | K28: 0.08359
J29: Intercept Quant/Qual (Unrestricted) | K29: 0.04155
J30: Intercept Final (Restricted) | K30: 0.04295
B33: Base Model
C34: Factors | D34: Raw Value | E34: Weight | F34: Raw Fitted Value | G34: Bucket # | I34: Std Fitted Value
B35: Economic | C35: =I10 -> Inflation 5 year average | D35: =IF(VLOOKUP($D$7,High_Seg2!$C:$BX,6,FALSE)="","",VLOOKUP($D$7,High_Seg2!$C:$BX,6,FALSE)) -> 2.2206 | E35: =M10 -> 0.088497113 | F35: =IF($D35="",VLOOKUP(9999999999,Buckets!$E$9:$M$15,8,TRUE),VLOOKUP($D35,Buckets!$E$9:$M$15,8,TRUE)) -> 1.2928828 | G35: =IF($D35="",VLOOKUP(9999999999,Buckets!$E$9:$M$15,9,TRUE),VLOOKUP($D35,Buckets!$E$9:$M$15,9,TRUE)) -> 1 | I35: =IF($D35="",VLOOKUP(9999999999,Buckets!$E$9:$M$15,7,TRUE),VLOOKUP($D35,Buckets!$E$9:$M$15,7,TRUE)) -> -0.9733
C36: =I11 -> Nominal Interest Rate Volatility | D36: =IF(VLOOKUP($D$7,High_Seg2!$C:$BX,16,FALSE)="","",VLOOKUP($D$7,High_Seg2!$C:$BX,16,FALSE)) -> 24.787811 | E36: =M11 -> 0.015734274 | F36: =IF($D36="",VLOOKUP(9999999999,Buckets!$E$138:$M$143,8,TRUE),VLOOKUP($D36,Buckets!$E$138:$M$143,8,TRUE)) -> 8.0021865 | G36: =IF($D36="",VLOOKUP(9999999999,Buckets!$E$138:$M$143,9,TRUE),VLOOKUP($D36,Buckets!$E$138:$M$143,9,TRUE)) -> 5 | I36: =IF($D36="",VLOOKUP(9999999999,Buckets!$E$138:$M$143,7,TRUE),VLOOKUP($D36,Buckets!$E$138:$M$143,7,TRUE)) -> -0.591
C37: =I12 -> GDP per Capita | D37: =IF(VLOOKUP($D$7,High_Seg2!$C:$BX,7,FALSE)="","",VLOOKUP($D$7,High_Seg2!$C:$BX,7,FALSE)) -> 48170 | E37: =M12 -> 0.1467073 | F37: =IF($D37="",VLOOKUP(999999999,Buckets!$E$19:$M$24,8,TRUE),VLOOKUP($D37,Buckets!$E$19:$M$24,8,TRUE)) -> -14130.835 | G37: =IF($D37="",VLOOKUP(999999999,Buckets!$E$19:$M$24,9,TRUE),VLOOKUP($D37,Buckets!$E$19:$M$24,9,TRUE)) -> 6 | I37: =IF($D37="",VLOOKUP(999999999,Buckets!$E$19:$M$24,7,TRUE),VLOOKUP($D37,Buckets!$E$19:$M$24,7,TRUE)) -> -1.5742
C38: =I13 -> Growth Volatility | D38: =IF(VLOOKUP($D$7,High_Seg2!$C:$BX,15,FALSE)="","",VLOOKUP($D$7,High_Seg2!$C:$BX,15,FALSE)) -> 2.5693265 | E38: =M13 -> 0.021542654 | F38: =IF($D38="",VLOOKUP(999999999,Buckets!$E$129:$M$134,8,TRUE),VLOOKUP($D38,Buckets!$E$129:$M$134,8,TRUE)) -> 1.779107 | G38: =IF($D38="",VLOOKUP(999999999,Buckets!$E$129:$M$134,9,TRUE),VLOOKUP($D38,Buckets!$E$129:$M$134,9,TRUE)) -> 4 | I38: =IF($D38="",VLOOKUP(999999999,Buckets!$E$129:$M$134,7,TRUE),VLOOKUP($D38,Buckets!$E$129:$M$134,7,TRUE)) -> -0.4183
C39: =I14 -> Macroeconomic | D39: =IF(VLOOKUP($D$7,High_Seg2!$C:$BX,10,FALSE)="","",VLOOKUP($D$7,High_Seg2!$C:$BX,10,FALSE)) -> 2 | E39: =M14 -> 0.081128016 | F39: =IF($D39="",VLOOKUP(9999999999,Buckets!$E$73:$M$78,8,TRUE),VLOOKUP($D39,Buckets!$E$73:$M$78,8,TRUE)) -> 2.1614379 | G39: =IF($D39="",VLOOKUP(9999999999,Buckets!$E$73:$M$78,9,TRUE),VLOOKUP($D39,Buckets!$E$73:$M$78,9,TRUE)) -> 2 | I39: =IF($D39="",VLOOKUP(9999999999,Buckets!$E$73:$M$78,7,TRUE),VLOOKUP($D39,Buckets!$E$73:$M$78,7,TRUE)) -> -1.1529
C41: Category Assessment | D41: =(SUMPRODUCT(K10:K14,I35:I39)+$K$25*E41)*Standardisation_Parameters!$F$2+Standardisation_Parameters!$E$2 -> 18.698955 | E41: =SUM(E35:E39) -> 0.35360935 | F41: =VLOOKUP($D41,$I$3:$P$8,8,TRUE) -> Very Low Risk
B43: Currency | C43: =I15 -> Access to Finance | D43: =IF(VLOOKUP($D$7,High_Seg2!$C:$BX,2,FALSE)="","",VLOOKUP($D$7,High_Seg2!$C:$BX,2,FALSE)) -> 1 | E43: =M15 -> 0.030288713 | F43: =IF($D43="",VLOOKUP(9999999999,Buckets!$E$4:$M$6,8,TRUE),VLOOKUP($D43,Buckets!$E$4:$M$6,8,TRUE)) -> 1.190268 | G43: =IF($D43="",VLOOKUP(9999999999,Buckets!$E$4:$M$6,9,TRUE),VLOOKUP($D43,Buckets!$E$4:$M$6,9,TRUE)) -> 1 | I43: =IF($D43="",VLOOKUP(9999999999,Buckets!$E$4:$M$6,7,TRUE),VLOOKUP($D43,Buckets!$E$4:$M$6,7,TRUE)) -> -0.7287
C44: =I16 -> Debt Trend | D44: =IF(VLOOKUP($D$7,High_Seg2!$C:$BX,8,FALSE)="","",VLOOKUP($D$7,High_Seg2!$C:$BX,8,FALSE)) -> 0.82238578 | E44: =M16 -> 0.027334477 | F44: =IF($D44="",VLOOKUP(9999999999,Buckets!$E$37:$M$42,8,TRUE),VLOOKUP($D44,Buckets!$E$37:$M$42,8,TRUE)) -> -15.191739 | G44: =IF($D44="",VLOOKUP(9999999999,Buckets!$E$37:$M$42,9,TRUE),VLOOKUP($D44,Buckets!$E$37:$M$42,9,TRUE)) -> 3 | I44: =IF($D44="",VLOOKUP(9999999999,Buckets!$E$37:$M$42,7,TRUE),VLOOKUP($D44,Buckets!$E$37:$M$42,7,TRUE)) -> -0.4274
...

Sheet Low Segment
I1: Low mapping
I2: Economic | J2: Currency | K2: Political | L2: Bus Risk | M2: Risk | N2: Overall
I3: 0 | J3: 0 | K3: 0 | L3: 0 | M3: 0 | N3: 0 | O3: Very Low Risk
B4: LOW HUMAN DEVELOPMENT | I4: 20 | J4: 20 | K4: 20 | L4: 20 | M4: 20 | N4: 20 | O4: Low Risk
I5: 40 | J5: 40 | K5: 40 | L5: 40 | M5: 40 | N5: 40 | O5: Moderate Risk
B6: Country Name | D6: SOUTH AFRICA | I6: 60 | J6: 60 | K6: 60 | L6: 60 | M6: 60 | N6: 60 | O6: High Risk
B7: ISO Code | D7: =VLOOKUP(D6,'Country List'!$A:$D,2,FALSE) -> ZAF | I7: 80 | J7: 80 | K7: 80 | L7: 80 | M7: 80 | N7: 80 | O7: Very High Risk
B8: HDI Segmentation | D8: =VLOOKUP(D7,'Country List'!$B:$D,2,FALSE) -> MEDIUM HUMAN DEVELOPMENT | I8: 100 | J8: 100 | K8: 100 | L8: 100 | M8: 100 | N8: 100 | O8: Default
B9: Region | D9: =VLOOKUP(D7,'Country List'!$B:$D,3,FALSE) -> AFRICA | I9: Model Drivers
I10: Inflation 5 year average | J10: dcpi_5_adj | K10: 0.43996 | L10: 0.16081591 | M10: =0.5*L10 -> 0.080407953 | N10: =SUM(M10:M12) -> 0.26381405 | O10: =SUM(N10:N15) -> 0.5
I11: Nominal Interest Rate | J11: nom_rir | K11: 0.30601 | L11: 0.082499404 | M11: =0.5*L11 -> 0.041249702
I12: Macroeconomic | J12: macro_var | K12: 0.63284 | L12: 0.28431279 | M12: =0.5*L12 -> 0.1421564
I13: Access to Finance | J13: atf | K13: 0.55294 | L13: 0.254189 | M13: =0.5*L13 -> 0.1270945 | N13: =SUM(M13:M15) -> 0.23618595
I14: Debt Trend | J14: DT | K14: 0.60889 | L14: 0.088012387 | M14: =0.5*L14 -> 0.044006193
I15: Debt Service Ratio 5 year average | J15: DSR_5year | K15: 1.11395 | L15: 0.13017051 | M15: =0.5*L15 -> 0.065085254
I16: Political Risk Environment | J16: pr | K16: 0.33987 | L16: 0.18188992 | M16: =0.5*L16 -> 0.090944962 | N16: =M16 -> 0.090944962 | O16: =SUM(N16:N19) -> 0.5
I17: Rule of Law | J17: rol | K17: 0.65754 | L17: 0.51294019 | M17: =0.5*L17 -> 0.25647009 | N17: =SUM(M17:M18) -> 0.34111244
I18: Doing Business | J18: db___rol_segmentation | K18: 0.33801 | L18: 0.16928469 | M18: =0.5*L18 -> 0.084642344
I19: Security Risk | J19: sr | K19: 0.23124 | L19: 0.1358852 | M19: =0.5*L19 -> 0.067942601 | N19: =M19 -> 0.067942601
I20: Quant | J20: yhat_quant | K20: 0.30517 | L20: 0.22605113 | M20: 0.22605113 | N20: 0.22605113 | O20: =SUM(N20:N21) -> 1
I21: Qual | J21: yhat_qualitative | K21: 0.83736 | L21: 0.77394887 | M21: 0.77394887 | N21: 0.77394887
I22: Quant | J22: yhat_quant with Restriction | K22: 0.675 | L22: 0.49999696 | M22: 0.49999696 | N22: =M22 -> 0.49999696 | O22: =SUM(N22:N23) -> 1
I23: Qual | J23: yhat_qualitative with Restriction | K23: 0.54096 | L23: 0.50000304 | M23: 0.50000304 | N23: =M23 -> 0.50000304
B24: Base Model | J24: Intercept Quant | K24: -1.9591
C25: Factors | D25: Raw Value | E25: Weight | F25: Raw Fitted Value | G25: Bucket # | I25: Std Fitted Value | J25: Intercept Qual | K25: -0.41692
B26: Economic | C26: =I10 -> Inflation 5 year average | D26: =IF(VLOOKUP($D$7,Low_Seg2!$C:$BE,2,FALSE)="","",VLOOKUP($D$7,Low_Seg2!$C:$BE,2,FALSE)) -> 6.5196 | E26: =M10 -> 0.080407953 | F26: =IF($D26="",VLOOKUP(9999999999,Buckets!$U$3:$AC$9,8,TRUE),VLOOKUP($D26,Buckets!$U$3:$AC$9,8,TRUE)) -> 10.600275 | G26: =IF($D26="",VLOOKUP(9999999999,Buckets!$U$3:$AC$9,9,TRUE),VLOOKUP($D26,Buckets!$U$3:$AC$9,9,TRUE)) -> 3 | I26: =IF($D26="",VLOOKUP(9999999999,Buckets!$U$3:$AC$9,7,TRUE),VLOOKUP($D26,Buckets!$U$3:$AC$9,7,TRUE)) -> 0.781 | J26: Intercept Quant/Qual (Unrestricted) | K26: -0.1046
C27: =I11 -> Nominal Interest Rate | D27: =IF(VLOOKUP($D$7,Low_Seg2!$C:$BE,4,FALSE)="","",VLOOKUP($D$7,Low_Seg2!$C:$BE,4,FALSE)) -> 9 | E27: =M11 -> 0.041249702 | F27: =IF($D27="",VLOOKUP(9999999999,Buckets!$U$30:$AC$35,8,TRUE),VLOOKUP($D27,Buckets!$U$30:$AC$35,8,TRUE)) -> 15.349915 | G27: =IF($D27="",VLOOKUP(9999999999,Buckets!$U$30:$AC$35,9,TRUE),VLOOKUP($D27,Buckets!$U$30:$AC$35,9,TRUE)) -> 1 | I27: =IF($D27="",VLOOKUP(9999999999,Buckets!$U$30:$AC$35,7,TRUE),VLOOKUP($D27,Buckets!$U$30:$AC$35,7,TRUE)) -> 0.4808 | J27: Intercept Final (Restricted) | K27: -0.15849
C28: =I12 -> Macroeconomic | D28: =IF(VLOOKUP($D$7,Low_Seg2!$C:$BE,3,FALSE)="","",VLOOKUP($D$7,Low_Seg2!$C:$BE,3,FALSE)) -> 4 | E28: =M12 -> 0.1421564 | F28: =IF($D28="",VLOOKUP(9999999999,Buckets!$U$13:$AC$18,8,TRUE),VLOOKUP($D28,Buckets!$U$13:$AC$18,8,TRUE)) -> 5.3660546 | G28: =IF($D28="",VLOOKUP(9999999999,Buckets!$U$13:$AC$18,9,TRUE),VLOOKUP($D28,Buckets!$U$13:$AC$18,9,TRUE)) -> 2 | I28: =IF($D28="",VLOOKUP(9999999999,Buckets!$U$13:$AC$18,7,TRUE),VLOOKUP($D28,Buckets!$U$13:$AC$18,7,TRUE)) -> 0.4707
C30: Category Assessment | D30: =(SUMPRODUCT(K10:K12,I26:I28)+$K$20*E30)*Standardisation_Parameters!$F$2+Standardisation_Parameters!$E$2 -> 59.198455 | E30: =SUM(E26:E28) -> 0.26381405 | F30: =VLOOKUP($D30,$I$3:$O$8,7,TRUE) -> Moderate Risk
B32: Currency | C32: =I13 -> Access to Finance | D32: =IF(VLOOKUP($D$7,Low_Seg2!$C:$BE,5,FALSE)="","",VLOOKUP($D$7,Low_Seg2!$C:$BE,5,FALSE)) -> 1 | E32: =M13 -> 0.1270945 | F32: =IF($D32="",VLOOKUP(9999999999,Buckets!$U$22:$AC$26,8,TRUE),VLOOKUP($D32,Buckets!$U$22:$AC$26,8,TRUE)) -> 2.7667357 | G32: =IF($D32="",VLOOKUP(9999999999,Buckets!$U$22:$AC$26,9,TRUE),VLOOKUP($D32,Buckets!$U$22:$AC$26,9,TRUE)) -> 1 | I32: =IF($D32="",VLOOKUP(9999999999,Buckets!$U$22:$AC$26,7,TRUE),VLOOKUP($D32,Buckets!$U$22:$AC$26,7,TRUE)) -> 0.332
C33: =I14 -> Debt Trend | D33: =IF(VLOOKUP($D$7,Low_Seg2!$C:$BE,11,FALSE)="","",VLOOKUP($D$7,Low_Seg2!$C:$BE,11,FALSE)) -> -21.24897 | E33: =M14 -> 0.044006193 | F33: =IF($D33="",VLOOKUP(9999999999,Buckets!$U$117:$AC$122,8,TRUE),VLOOKUP($D33,Buckets!$U$117:$AC$122,8,TRUE)) -> 28.939827 | G33: =IF($D33="",VLOOKUP(9999999999,Buckets!$U$117:$AC$122,9,TRUE),VLOOKUP($D33,Buckets!$U$117:$AC$122,9,TRUE)) -> 3 | I33: =IF($D33="",VLOOKUP(9999999999,Buckets!$U$117:$AC$122,7,TRUE),VLOOKUP($D33,Buckets!$U$117:$AC$122,7,TRUE)) -> 0.7245
C34: =I15 -> Debt Service Ratio 5 year average | D34: =IF(VLOOKUP($D$7,Low_Seg2!$C:$BE,6,FALSE)="","",VLOOKUP($D$7,Low_Seg2!$C:$BE,6,FALSE)) -> 5.1372 | E34: =M15 -> 0.065085254 | F34: =IF($D34="",VLOOKUP(9999999999,Buckets!$U$39:$AC$44,8,TRUE),VLOOKUP($D34,Buckets!$U$39:$AC$44,8,TRUE)) -> 17.520085 | G34: =IF($D34="",VLOOKUP(9999999999,Buckets!$U$39:$AC$44,9,TRUE),VLOOKUP($D34,Buckets!$U$39:$AC$44,9,TRUE)) -> 3 | I34: =IF($D34="",VLOOKUP(9999999999,Buckets!$U$39:$AC$44,7,TRUE),VLOOKUP($D34,Buckets!$U$39:$AC$44,7,TRUE)) -> 0.6933
C36: Category Assessment | D36: =(SUMPRODUCT(K13:K15,I32:I34)+$K$20*$E$36)*Standardisation_Parameters!$F$2+Standardisation_Parameters!$E$2 -> 69.227 | E36: =SUM(E32:E34) -> 0.23618595 | F36: =VLOOKUP($D36,$J$3:$O$8,6,TRUE) -> High Risk
B38: Political | C38: =I16 -> Political Risk Environment | D38: =IF(VLOOKUP($D$7,Low_Seg2!$C:$BE,7,FALSE)="","",VLOOKUP($D$7,Low_Seg2!$C:$BE,7,FALSE)) -> 3 | E38: =M16 -> 0.090944962 | F38: =IF($D38="",VLOOKUP(9999999999,Buckets!$U$50:$AC$54,8,TRUE),VLOOKUP($D38,Buckets!$U$50:$AC$54,8,TRUE)) -> 4.4199 | G38: =IF($D38="",VLOOKUP(9999999999,Buckets!$U$50:$AC$54,9,TRUE),VLOOKUP($D38,Buckets!$U$50:$AC$54,9,TRUE)) -> 1 | I38: =IF($D38="",VLOOKUP(9999999999,Buckets!$U$50:$AC$54,7,TRUE),VLOOKUP($D38,Buckets!$U$50:$AC$54,7,TRUE)) -> 0.296
C40: Category Assessment | D40: =((I38*K16)+$K$21*$E$40)*Standardisation_Parameters!$F$2+Standardisation_Parameters!$E$2 -> 47.625472 | E40: =SUM(E38) -> 0.090944962 | F40: =VLOOKUP($D40,$K$3:$O$8,5,TRUE) -> Moderate Risk
B42: Business Risk | C42: =I17 -> Rule of Law | D42: =IF(VLOOKUP($D$7,Low_Seg2!$C:$BE,8,FALSE)="","",VLOOKUP($D$7,Low_Seg2!$C:$BE,8,FALSE)) -> 0.10025151 | E42: =M17 -> 0.25647009 | F42: =IF($D42="",VLOOKUP(9999999999,Buckets!$U$58:$AC$63,8,TRUE),VLOOKUP($D42,Buckets!$U$58:$AC$63,8,TRUE)) -> 0.14792011 | G42: =IF($D42="",VLOOKUP(9999999999,Buckets!$U$58:$AC$63,9,TRUE),VLOOKUP($D42,Buckets!$U$58:$AC$63,9,TRUE)) -> 6 | I42: =IF($D42="",VLOOKUP(9999999999,Buckets!$U$58:$AC$63,7,TRUE),VLOOKUP($D42,Buckets!$U$58:$AC$63,7,TRUE)) -> 0.1036
C43: =I18 -> Doing Business | D43: =IF(VLOOKUP($D$7,Low_Seg2!$C:$BE,9,FALSE)="","",VLOOKUP($D$7,Low_Seg2!$C:$BE,9,FALSE)) -> 19.672131 | E43: =M18 -> 0.084642344 | F43: =IF($D43="",IF($D42<0,VLOOKUP(9999999999,Buckets!$S$76:$AC$78,10,TRUE),VLOOKUP(9999999999,Buckets!$S$84:$AC$86,10,TRUE)),IF($D42<0,VLOOKUP((($D43-Standardisation_Parameters!$E$15)/Standardisation_Parameters!$F$15),Buckets!$S$76:$AC$78,10,TRUE),VLOOKUP((($D43-Standardisation_Parameters!$E$15)/Standardisation_Parameters!$F$15),Buckets!$S$84:$AC$86,10,TRUE))) -> 37.062615 | G43: =IF($D43="",IF($D42<0,VLOOKUP(9999999999,Buckets!$S$76:$AC$78,11,TRUE),VLOOKUP(9999999999,Buckets!$S$84:$AC$86,11,TRUE)),IF($D42<0,VLOOKUP((($D43-Standardisation_Parameters!$E$15)/Standardisation_Parameters!$F$15),Buckets!$S$76:$AC$78,11,TRUE),VLOOKUP((($D43-Standardisation_Parameters!$E$15)/Standardisation_Parameters!$F$15),Buckets!$S$84:$AC$86,11,TRUE))) -> 1 | I43: =IF($D43="",IF($D42<0,VLOOKUP(9999999999,Buckets!$S$76:$AC$78,9,TRUE),VLOOKUP(9999999999,Buckets!$S$84:$AC$86,9,TRUE)),IF($D42<0,VLOOKUP((($D43-Standardisation_Parameters!$E$15)/Standardisation_Parameters!$F$15),Buckets!$S$76:$AC$78,9,TRUE),VLOOKUP((($D43-Standardisation_Parameters!$E$15)/Standardisation_Parameters!$F$15),Buckets!$S$84:$AC$86,9,TRUE))) -> -0.2519
C45: Category Assessment | D45: =(SUMPRODUCT(K17:K18,I42:I43)+$K$21*$E$45)*Standardisation_Parameters!$F$2+Standardisation_Parameters!$E$2 -> 49.160835 | E45: =SUM(E41:E43) -> 0.34111244 | F45: =VLOOKUP($D45,$L$3:$O$8,4,TRUE) -> Moderate Risk
B47: Risk | C47: =I19 -> Security Risk | D47: =IF(VLOOKUP($D$7,Low_Seg2!$C:$BE,10,FALSE)="","",VLOOKUP($D$7,Low_Seg2!$C:$BE,10,FALSE)) -> 3.25 | E47: =M19 -> 0.067942601 | F47: =IF($D47="",VLOOKUP(9999999999,Buckets!$U$67:$AC$72,8,TRUE),VLOOKUP($D47,Buckets!$U$67:$AC$72,8,TRUE)) -> 3.4408471 | G47: =IF($D47="",VLOOKUP(9999999999,Buckets!$U$67:$AC$72,9,TRUE),VLOOKUP($D47,Buckets!$U$67:$AC$72,9,TRUE)) -> 4 | I47: =IF($D47="",VLOOKUP(9999999999,Buckets!$U$67:$AC$72,7,TRUE),VLOOKUP($D47,Buckets!$U$67:$AC$72,7,TRUE)) -> 0.8224
C49: Category Assessment | D49: =((I47*K19)+$K$21*$E$49)*Standardisation_Parameters!$F$2+Standardisation_Parameters!$E$2 -> 48.80069 | E49: =SUM(E47:E47) -> 0.067942601 | F49: =VLOOKUP($D49,$M$3:$O$8,3,TRUE) -> Moderate Risk
...

Sheet No Data Segment
L1: Low mapping
L2: Economic | M2: Currency | N2: Political | O2: Bus Risk | P2: Risk | Q2: Overall
L3: 0 | M3: 0 | N3: 0 | O3: 0 | P3: 0 | Q3: 0 | R3: Very Low Risk
B4: NO DATA | L4: 20 | M4: 20 | N4: 20 | O4: 20 | P4: 20 | Q4: 20 | R4: Low Risk
L5: 40 | M5: 40 | N5: 40 | O5: 40 | P5: 40 | Q5: 40 | R5: Moderate Risk
B6: Country Name | F6: JERSEY | L6: 60 | M6: 60 | N6: 60 | O6: 60 | P6: 60 | Q6: 60 | R6: High Risk
B7: ISO Code | F7: =IFERROR(VLOOKUP(F6,'Country List'!$A:$D,2,FALSE),"") -> JEY | L7: 80 | M7: 80 | N7: 80 | O7: 80 | P7: 80 | Q7: 80 | R7: Very High Risk
B8: HDI Segmentation | F8: =IFERROR(VLOOKUP(F7,'Country List'!$B:$D,2,FALSE),"") -> VERY HIGH HUMAN DEVELOPMENT | L8: 100 | M8: 100 | N8: 100 | O8: 100 | P8: 100 | Q8: 100 | R8: Default
B9: Region | F9: =IFERROR(VLOOKUP(F7,'Country List'!$B:$D,3,FALSE),"") -> DEVELOPED MARKET
C12: Agency | D12: Score | E12: Bucket | F12: Risk
C13: EIU Rating | D13: =IFERROR(VLOOKUP($F$7,Nodata_Raw!$C:$D,2,FALSE),"No Dependent Variable") -> 19 | E13: =IFERROR(ROUND(D13/5,0),"") -> 4 | F13: =IFERROR(VLOOKUP(D13,$Q$3:$R$8,2,TRUE),"") -> Very Low Risk

Sheet HelpSheet
A1: Help Page | B1: Welcome to the Country Model The help notes are arranged by Tab. Either select a tab from the drop down below or scroll through the notes using the next/previous buttons.
A2: Home | B2: This is a dashboard for quick navigation through the pages in this spreadsheet. ---------------------------------------------------------------------- Simply click on the country you wish to rate or the segment that you wish to visit.
A3: High Segment | B3: The High Segment allows the user to select high segment countries that they would like to rate. ---------------------------------------------------------------------- In the drop down menu choose/select a country. The Base Model section is automatically updated with source information that produces a base model rating for a given country. If you are happy with the base model score select Yes if not and the use would like to adjsut the score select No. Yes will direct the user to the final overall rating, No will direct the user to the adjustment section. Adjustment Section: Answer the category questions and select approporiate answers from the drop down lists. The user is urged to answer all questions and to select "Not Applicable" if they do not wish to answer a specific question.
A4: Low Segment | B4: The Low Segment allows the user to select low segment countries that they would like to rate. ---------------------------------------------------------------------- In the drop down menu choose/select a country. The Base Model section is automatically updated with source information that produces a base model rating for a given country. If you are happy with the base model score select Yes if not and the use would like to adjsut the score select No. Yes will direct the user to the final overall rating, No will direct the user to the adjustment section. Adjustment Section: Answer the category questions and select approporiate answers from the drop down lists. The user is urged to answer all questions and to select "Not Applicable" if they do not wish to answer a specific question.
A5: No Data Segment | B5: The No Data Segment allows the user to select no data segment countries that they would like to rate using external agency ratings. ---------------------------------------------------------------------- In the drop down menu choose/select a country. Select an appropriate agency to use and the rating will automatically be updated with rating source information for the given country from the selected agency.

Sheet Standardisation_Parameters
A1: _STAT_ | B1: N | C1: MIN | D1: MAX | E1: MEAN | F1: STD | H1: _STAT_ | I1: N | J1: MIN | K1: MAX | L1: MEAN | M1: STD
A2: EIU_Score | B2: 794 | C2: 7.44 | D2: 90.11 | E2: 44.671 | F2: 16.715049 | H2: EIU_Score | I2: 794 | J2: 7.44 | K2: 90.11 | L2: 44.671 | M2: 16.715049
A3: DCPI_5 | B3: 794 | C3: -0.68 | D3: 57.39 | E3: 6.4567 | F3: 5.3054733 | H3: DCPI_5 | I3: 794 | J3: -0.68 | K3: 57.386 | L3: 6.4567 | M3: 5.3054733
A4: macro_var | B4: 794 | C4: 1 | D4: 9 | E4: 4.437 | F4: 1.9737723 | H4: macro_var | I4: 794 | J4: 1 | K4: 9 | L4: 4.437 | M4: 1.9737723
A5: ATF | B5: 794 | C5: 1 | D5: 6 | E5: 2.2733 | F5: 1.4862522 | H5: ATF | I5: 794 | J5: 1 | K5: 6 | L5: 2.2733 | M5: 1.4862522
A6: Nom_RIR | B6: 794 | C6: 1.48 | D6: 65.39 | E6: 11.767 | F6: 7.4519868 | H6: Nom_RIR | I6: 794 | J6: 1.475 | K6: 65.392 | L6: 11.767 | M6: 7.4519868
A7: DSR | B7: 794 | C7: -0.22 | D7: 91.6 | E7: 9.2081 | F7: 11.648243 | H7: DSR | I7: 794 | J7: -0.223 | K7: 91.6 | L7: 9.2081 | M7: 11.648243
A8: DSR_5year | B8: 794 | C8: 0.02 | D8: 76.66 | E8: 10.193 | F8: 10.568419 | H8: DSR_5year | I8: 794 | J8: 0.0173 | K8: 76.66 | L8: 10.193 | M8: 10.568419
A9: GROWTH_VOL | B9: 794 | C9: 0.2 | D9: 20.68 | E9: 2.7613 | F9: 2.3480587 | H9: GROWTH_VOL | I9: 794 | J9: 0.205 | K9: 20.678651 | L9: 2.7613 | M9: 2.3480587
A10: CAB_FDI | B10: 794 | C10: -43.08 | D10: 43.31 | E10: 1.5885 | F10: 10.355063 | H10: CAB_FDI | I10: 794 | J10: -43.08 | K10: 43.308269 | L10: 1.5885 | M10: 10.355063
A11: GDP_CAPITA | B11: 794 | C11: 164.2 | D11: 104570 | E11: 14228 | F11: 18014.76 | H11: GDP_CAPITA | I11: 794 | J11: 164.2 | K11: 104570 | L11: 14228 | M11: 18014.76
A12: COF | B12: 794 | C12: 0.08 | D12: 70 | E12: 6.1683 | F12: 5.3562941 | H12: COF | I12: 794 | J12: 0.08 | K12: 70 | L12: 6.1683 | M12: 5.3562941
A13: DT | B13: 794 | C13: -87.79 | D13: 359.62 | E13: 1.1828 | F13: 38.311976 | H13: DT | I13: 794 | J13: -87.79 | K13: 359.6188 | L13: 1.1828 | M13: 38.311976
... A21: XCM | B21: 794 | C21: 0 | D21: 85.68 | E21: 25.17 | F21: 15.843089 | H21: XCM | I21: 794 | J21: 0 | K21: 85.684 | L21: 25.17 | M21: 15.843089
A22: Nom_RIR_VOL | B22: 794 | C22: 0 | D22: 78.519056 | E22: 14.6 | F22: 11.163813

Sheet Buckets
A1: HIGH SEGMENT BASE MODEL | Q1: LOW SEGMENT BASE MODEL | AH1: GDP | AI1: Attributes | AJ1: Response
Q2: Buckets | R2: DCPI_5_Adj | S2: Min | T2: Max | U2: RAW Min | W2: Frequency | X2: Average EIU | Z2: Category Num | AA2: EIU Fitted | AB2: EIU Fitted Raw | AC2: Category Num | AH2: GDP per capita provides an incomplete picture of development in the country, given the high degree of income inequality (as measured by the GINI coefficient) | AI2: Applicable | AJ2: -1
A3: Buckets | B3: ATF | C3: Min | D3: Max | G3: Frequency | H3: Average EIU | J3: Category Num | K3: EIU Fitted | L3: EIU Fitted Raw | M3: Category Num | R3: 1 | T3: 0 | U3: -9999999999 | V3: 0 | X3: 0.54862195 | Z3: 2 | AA3: 0.5845 | AB3: =AA3*Standardisation_Parameters!$F$3+Standardisation_Parameters!$E$3 -> 9.5577491 | AC3: 1 | AI3: Not applicable | AJ3: 0
A4: ="<= " &F4 -> <= 1 | B4: 1 | C4: 1 | D4: 1 | E4: -9999999999 | F4: =ROUND(D4,2) -> 1 | G4: 299 | H4: -0.88594772 | J4: 1 | K4: -0.7287 | L4: =K4*Standardisation_Parameters!$F$5+Standardisation_Parameters!$E$5 -> 1.190268 | M4: 1 | Q4: <= 3 | R4: 0 | S4: 0 | T4: 3 | U4: 0 | V4: 3 | W4: 39 | X4: 0.58864962 | Z4: 1 | AA4: 0.388 | AB4: =AA4*Standardisation_Parameters!$F$3+Standardisation_Parameters!$E$3 -> 8.5152236 | AC4: 1
A5: [2 : 2] | B5: 4 | C5: 2 | D5: 2 | E5: =ROUND(C5,2) -> 2 | F5: =ROUND(D5,2) -> 2 | G5: 88 | H5: 0.13776324 | J5: 2 | K5: -0.1767 | L5: =K5*Standardisation_Parameters!$F$5+Standardisation_Parameters!$E$5 -> 2.0106792 | M5: 2 | Q5: (3 : 6] | R5: 1 | S5: 3 | T5: 6 | U5: 3 | V5: 6 | W5: 74 | X5: 0.54862195 | Z5: 2 | AA5: 0.5845 | AB5: =AA5*Standardisation_Parameters!$F$3+Standardisation_Parameters!$E$3 -> 9.5577491 | AC5: 2
A6: > 2 | B6: 5 | C6: 3 | D6: 6 | E6: =ROUND(C6,2) -> 3 | F6: -9999999999 | G6: 89 | H6: 0.21801705 | J6: 3 | K6: 0.3753 | L6: =K6*Standardisation_Parameters!$F$5+Standardisation_Parameters!$E$5 -> 2.8310905 | M6: 3 | Q6: (6 : 10] | R6: 2 | S6: 6 | T6: 10 | U6: 6 | V6: 10 | W6: 102 | X6: 0.64005279 | Z6: 3 | AA6: 0.781 | AB6: =AA6*Standardisation_Parameters!$F$3+Standardisation_Parameters!$E$3 -> 10.600275 | AC6: 3 | AH6: Export Market | AI6: Attributes | AJ6: Response
Q7: (10 : 15] | R7: 3 | S7: 10 | T7: 15 | U7: 10 | V7: 15 | W7: 81 | X7: 0.94352377 | Z7: 4 | AA7: 0.9775 | AB7: =AA7*Standardisation_Parameters!$F$3+Standardisation_Parameters!$E$3 -> 11.6428 | AC7: 4 | AH7: Exposure to an adverse export market (may either be one country or a grouping of countries) poses a significant concentration risk; | AI7: Concentration to adverse export market | AJ7: -1
A8: Buckets | B8: dcpi_5_adj | C8: Min | D8: Max | G8: Frequency | H8: Average EIU | J8: Category Num | K8: EIU Fitted | L8: EIU Fitted Raw | M8: Category Num | Q8: (15 : 20] | R8: 4 | S8: 15 | T8: 20 | U8: 15 | V8: 20 | W8: 11 | X8: 0.80585637 | Z8: 5 | AA8: 1.174 | AB8: =AA8*Standardisation_Parameters!$F$3+Standardisation_Parameters!$E$3 -> 12.685326 | AC8: 5 | AI8: No concentration risk | AJ8: 0
B9: 1 | D9: 0 | E9: -9999999999 | F9: 0 | H9: -0.33542548 | J9: 2 | K9: -0.5387 | L9: =K9*Standardisation_Parameters!$F$3+Standardisation_Parameters!$E$3 -> 3.5986415 | M9: 2 | Q9: > 20 | R9: 5 | S9: 20 | T9: 57.39 | U9: 20 | V9: 9999999999 | W9: 11 | X9: 1.7491906 | Z9: 6 | AA9: 1.3705 | AB9: =AA9*Standardisation_Parameters!$F$3+Standardisation_Parameters!$E$3 -> 13.727851 | AC9: 6
A10: <= 3 | B10: 0 | C10: 0 | D10: 3 | E10: 0 | F10: 3 | G10: 207 | H10: -1.0651401 | J10: 1 | K10: -0.9733 | L10: =K10*Standardisation_Parameters!$F$3+Standardisation_Parameters!$E$3 -> 1.2928828 | M10: 1
A11: (3 : 6] | B11: 1 | C11: 3 | D11: 6 | E11: 3 | F11: 6 | G11: 132 | H11: -0.33542548 | J11: 2 | K11: -0.5387 | L11: =K11*Standardisation_Parameters!$F$3+Standardisation_Parameters!$E$3 -> 3.5986415 | M11: 2 | AH11: CMA | AI11: Attributes | AJ11: Response
A12: (6 : 10] | B12: 2 | C12: 6 | D12: 10 | E12: 6 | F12: 10 | G12: 64 | H12: -0.15925001 | J12: 3 | K12: -0.0591 | L12: =K12*Standardisation_Parameters!$F$3+Standardisation_Parameters!$E$3 -> 6.1431465 | M12: 3 | R12: Macro_var | S12: Min | T12: Max | W12: Frequency | X12: Average EIU | Z12: Category Num | AA12: EIU Fitted | AC12: Category Num | AH12: Existence of a managed exchange rate regime or member of Common Monetary Area (CMA) | AI12: Sustainable and provides stability | AJ12: 1
A13: (10 : 15] | B13: 3 | C13: 10 | D13: 15 | E13: 10 | F13: 15 | G13: 50 | H13: 0.46492233 | J13: 4 | K13: 0.4655 | L13: =K13*Standardisation_Parameters!$F$3+Standardisation_Parameters!$E$3 -> 8.9263978 | M13: 4 | Q13: <= -0.69 | R13: 0 | S13: 2 | T13: 3 | U13: -9999999999 | V13: 3 | W13: 43 | X13: 0.23056616 | Z13: 1 | AA13: 0.3023 | AB13: =AA13*Standardisation_Parameters!$F$4+Standardisation_Parameters!$E$4 -> 5.0336714 | AC13: 1 | AI13: Unsustainable peg or encumbers monetary policy | AJ13: -1
A14: (15 : 20] | B14: 4 | C14: 15 | D14: 20 | E14: 15 | F14: 20 | G14: 9 | H14: 0.98279659 | J14: 5 | K14: 1.0351 | L14: =K14*Standardisation_Parameters!$F$3+Standardisation_Parameters!$E$3 -> 11.948395 | M14: 5 | Q14: (-0.69 : -0.18] | R14: 1 | S14: 4 | T14: 4 | U14: 4 | V14: 4 | W14: 60 | X14: 0.56043418 | Z14: 2 | AA14: 0.4707 | AB14: =AA14*Standardisation_Parameters!$F$4+Standardisation_Parameters!$E$4 -> 5.3660546 | AC14: 2 | AI14: No impact | AJ14: 0
A15: > 20 | B15: 5 | C15: 20 | D15: 21.28 | E15: 20 | F15: -9999999999 | G15: 7 | H15: 1.6910253 | J15: 6 | K15: 1.6497 | L15: =K15*Standardisation_Parameters!$F$3+Standardisation_Parameters!$E$3 -> 15.209139 | M15: 6 | Q15: (-0.18 : 0.32] | R15: 2 | S15: 5 | T15: 5 | U15: 5 | V15: 5 | W15: 80 | X15: 0.73860667 | Z15: 3 | AA15: 0.6471 | AB15: =AA15*Standardisation_Parameters!$F$4+Standardisation_Parameters!$E$4 -> 5.7142281 | AC15: 3
Q16: (0.32 : 0.83] | R16: 3 | S16: 6 | T16: 6 | U16: 6 | V16: 6 | W16: 44 | X16: 0.7373084 | Z16: 4 | AA16: 0.8315 | AB16: =AA16*Standardisation_Parameters!$F$4+Standardisation_Parameters!$E$4 -> 6.0781917 | AC16: 4 | AH16: Political Risk | AI16: Attributes | AJ16: Category Notching
Q17: (0.83 : 1.33] | R17: 4 | S17: 7 | T17: 7 | U17: 7 | V17: 7 | W17: 55 | X17: 0.93948421 | Z17: 5 | AA17: 1.0239 | AB17: =AA17*Standardisation_Parameters!$F$4+Standardisation_Parameters!$E$4 -> 6.4579455 | AC17: 5 | AH17: There is a risk of war within the country territory, but the risk is not expected to materialise within the next 3 years | AI17: High probability | AJ17: 2
A18: Buckets | B18: GDP_Capita | C18: Min | D18: Max | G18: Frequency | H18: Average EIU | J18: Category Num | K18: EIU Fitted | M18: Category Num | Q18: > 1.33 | R18: 5 | S18: 8 | T18: 9 | U18: 8 | V18: 9999999999 | W18: 36 | X18: 1.2952654 | Z18: 6 | AA18: 1.2243 | AB18: =AA18*Standardisation_Parameters!$F$4+Standardisation_Parameters!$E$4 -> 6.8534894 | AC18: 6 | AI18: Moderate probability | AJ18: 1
A19: <= -0.5 | B19: 0 | C19: -0.69207701 | D19: -0.50359823 | E19: -9999999999 | F19: =D19*Standardisation_Parameters!$F$11+Standardisation_Parameters!$E$11 -> 5155.7987 | G19: 79 | H19: 0.53179603 | J19: 1 | K19: 0.5588 | L19: =K19*Standardisation_Parameters!$F$11+Standardisation_Parameters!$E$11 -> 24294.648 | M19: 1 | AI19: Not Applicable | AJ19: 0
A20: (-0.5 : -0.3] | B20: 1 | C20: -0.50009555 | D20: -0.29905485 | E20: =C20*Standardisation_Parameters!$F$11+Standardisation_Parameters!$E$11 -> 5218.8987 | F20: =D20*Standardisation_Parameters!$F$11+Standardisation_Parameters!$E$11 -> 8840.5987 | G20: 79 | H20: 0.16626812 | J20: 2 | K20: 0.153 | L20: =K20*Standardisation_Parameters!$F$11+Standardisation_Parameters!$E$11 -> 16984.258 | M20: 2
A21: (-0.3 : 0.03] | B21: 2 | C21: -0.29808342 | D21: 0.010863244 | E21: =C21*Standardisation_Parameters!$F$11+Standardisation_Parameters!$E$11 -> 8858.0987 | F21: =D21*Standardisation_Parameters!$F$11+Standardisation_Parameters!$E$11 -> 14423.699 | G21: 80 | H21: -0.18005981 | J21: 3 | K21: -0.2632 | L21: =K21*Standardisation_Parameters!$F$11+Standardisation_Parameters!$E$11 -> 9486.5152 | M21: 3 | Q21: Buckets | R21: ATF | S21: Min | T21: Max | W21: Frequency | X21: Average EIU | Z21: Category Num | AA21: EIU Fitted | AC21: Category Num | AH21: Debt Service | AI21: Attributes | AJ21: Notching
A22: (0.03 : 0.78] | B22: 3 | C22: 0.025118222 | D22: 0.72931856 | E22: =C22*Standardisation_Parameters!$F$11+Standardisation_Parameters!$E$11 -> 14680.499 | F22: =D22*Standardisation_Parameters!$F$11+Standardisation_Parameters!$E$11 -> 27366.499 | G22: 79 | H22: -0.74372902 | J22: 4 | K22: -0.6898 | L22: =K22*Standardisation_Parameters!$F$11+Standardisation_Parameters!$E$11 -> 1801.4186 | M22: 4 | Q22: <= 1 | R22: 0 | S22: 1 | T22: 1 | U22: -9999999999 | V22: 1 | W22: 63 | X22: 0.31408493 | Z22: 1 | AA22: 0.332 | AB22: =AA22*Standardisation_Parameters!$F$5+Standardisation_Parameters!$E$5 -> 2.7667357 | AC22: 1 | AH22: In addition to the nominal level of external debt, debt serviceability improves/impedes the rating. | AI22: No impact | AJ22: 0
A23: (0.78 : 1.7] | B23: 4 | C23: 0.73641829 | D23: 1.66655 | E23: =C23*Standardisation_Parameters!$F$11+Standardisation_Parameters!$E$11 -> 27494.399 | F23: =D23*Standardisation_Parameters!$F$11+Standardisation_Parameters!$E$11 -> 44250.499 | G23: 80 | H23: -1.1798898 | J23: 5 | K23: -1.1268 | L23: =K23*Standardisation_Parameters!$F$11+Standardisation_Parameters!$E$11 -> -6071.0316 | M23: 5 | Q23: (1 : 2.5] | R23: 1 | S23: 2 | T23: 2.5 | U23: 2 | V23: 2.5 | W23: 55 | X23: 0.56625737 | Z23: 2 | AA23: 0.513 | AB23: =AA23*Standardisation_Parameters!$F$5+Standardisation_Parameters!$E$5 -> 3.0357474 | AC23: 2 | AI23: Low debt service | AJ23: 1
A24: > 1.7 | B24: 5 | C24: 1.6726395 | D24: 5.0149155 | E24: =C24*Standardisation_Parameters!$F$11+Standardisation_Parameters!$E$11 -> 44360.199 | F24: 9999999999 | G24: 79 | H24: -1.5312429 | J24: 6 | K24: -1.5742 | L24: =K24*Standardisation_Parameters!$F$11+Standardisation_Parameters!$E$11 -> -14130.835 | M24: 6 | Q24: (2.5 : 3] | R24: 2 | S24: 3 | T24: 3 | U24: 3 | V24: 3 | W24: 77 | X24: 0.66492696 | Z24: 3 | AA24: 0.7174 | AB24: =AA24*Standardisation_Parameters!$F$5+Standardisation_Parameters!$E$5 -> 3.3395373 | AC24: 3 | AI24: high debt service | AJ24: -1
Q25: (3 : 4] | R25: 3 | S25: 4 | T25: 4 | U25: 4 | V25: 4 | W25: 68 | X25: 0.96195199 | Z25: 4 | AA25: 0.9452 | AB25: =AA25*Standardisation_Parameters!$F$5+Standardisation_Parameters!$E$5 -> 3.6781056 | AC25: 4
Q26: > 4 | R26: 4 | S26: 5 | T26: 6 | U26: 5 | V26: 9999999999 | W26: 55 | X26: 1.196874 | Z26: 5 | AA26: 1.1964 | AB26: =AA26*Standardisation_Parameters!$F$5+Standardisation_Parameters!$E$5 -> 4.0514521 | AC26: 5 | AH26: Inflation | AI26: Attributes | AJ26: Response
A27: Buckets | B27: COF | C27: Min | D27: Max | G27: Frequency | H27: Average EIU | J27: Category Num | K27: EIU Fitted | M27: Category Num | AH27: IS the inflation great than 10.5%? | AI27: Yes | AJ27: -1
A28: <= -0.86 | B28: 0 | C28: -1.1290053 | D28: -0.92531974 | E28: -9999999999 | F28: =D28*Standardisation_Parameters!$F$12+Standardisation_Parameters!$E$12 -> 1.2120153 | G28: 78 | H28: -1.1304607 | J28: 1 | K28: -1.2093 | L28: =K28*Standardisation_Parameters!$F$12+Standardisation_Parameters!$E$12 -> -0.30906646 | M28: 1 | AI28: No | AJ28: 0
A29: (-0.86 : -0.56] | B29: 1 | C29: -0.9223326 | D29: -0.5838523 | E29: =C29*Standardisation_Parameters!$F$12+Standardisation_Parameters!$E$12 -> 1.2280153 | F29: =D29*Standardisation_Parameters!$F$12+Standardisation_Parameters!$E$12 -> 3.0410153 | G29: 80 | H29: -0.83365994 | J29: 2 | K29: -0.9205 | L29: =K29*Standardisation_Parameters!$F$12+Standardisation_Parameters!$E$12 -> 1.2378313 | M29: 2 | Q29: Buckets | R29: Nom_Rir | S29: Min | T29: Max | W29: Frequency | X29: Average EIU | Z29: Category Num | AA29: EIU Fitted | AC29: Category Num
A30: (-0.56 : -0.36] | B30: 2 | C30: -0.57843811 | D30: -0.34805494 | E30: =C30*Standardisation_Parameters!$F$12+Standardisation_Parameters!$E$12 -> 3.0700153 | F30: =D30*Standardisation_Parameters!$F$12+Standardisation_Parameters!$E$12 -> 4.3040154 | G30: 80 | H30: -0.91407981 | J30: 3 | K30: -0.6317 | L30: =K30*Standardisation_Parameters!$F$12+Standardisation_Parameters!$E$12 -> 2.784729 | M30: 3 | Q30: <= -0.43 | R30: 0 | S30: -1.0020082 | T30: -0.3686201 | U30: -9999999999 | V30: =T30*Standardisation_Parameters!$F$6+Standardisation_Parameters!$E$6 -> 9.0200479 | W30: 53 | X30: 0.57734774 | Z30: 1 | AA30: 0.4808 | AB30: =AA30*Standardisation_Parameters!$F$6+Standardisation_Parameters!$E$6 -> 15.349915 | AC30: 1
A31: (-0.36 : -0.15] | B31: 3 | C31: -0.34357423 | D31: -0.1662128 | E31: =C31*Standardisation_Parameters!$F$12+Standardisation_Parameters!$E$12 -> 4.3280154 | F31: =D31*Standardisation_Parameters!$F$12+Standardisation_Parameters!$E$12 -> 5.2780154 | G31: 83 | H31: -0.37313778 | J31: 4 | K31: -0.3429 | L31: =K31*Standardisation_Parameters!$F$12+Standardisation_Parameters!$E$12 -> 4.3316268 | M31: 4 | Q31: (-0.43 : -0.22] | R31: 1 | S31: -0.36727818 | T31: 0.031273252 | U31: =S31*Standardisation_Parameters!$F$6+Standardisation_Parameters!$E$6 -> 9.0300479 | V31: =T31*Standardisation_Parameters!$F$6+Standardisation_Parameters!$E$6 -> 12.000048 | W31: 53 | X31: 0.50845591 | Z31: 2 | AA31: 0.582 | AB31: =AA31*Standardisation_Parameters!$F$6+Standardisation_Parameters!$E$6 -> 16.104056 | AC31: 2
A32: (-0.15 : 0.24] | B32: 4 | C32: -0.16210548 | D32: 0.24862626 | E32: =C32*Standardisation_Parameters!$F$12+Standardisation_Parameters!$E$12 -> 5.3000154 | F32: =D32*Standardisation_Parameters!$F$12+Standardisation_Parameters!$E$12 -> 7.5000154 | G32: 76 | H32: 0.11336807 | J32: 5 | K32: -0.0541 | L32: =K32*Standardisation_Parameters!$F$12+Standardisation_Parameters!$E$12 -> 5.8785245 | M32: 5 | Q32: (-0.22 : -0.07] | R32: 2 | S32: 0.050060188 | T32: 0.34930924 | U32: =S32*Standardisation_Parameters!$F$6+Standardisation_Parameters!$E$6 -> 12.140048 | V32: =T32*Standardisation_Parameters!$F$6+Standardisation_Parameters!$E$6 -> 14.370048 | W32: 53 | X32: 0.6625018 | Z32: 3 | AA32: 0.6832 | AB32: =AA32*Standardisation_Parameters!$F$6+Standardisation_Parameters!$E$6 -> 16.858197 | AC32: 3
A33: > 0.24 | B33: 5 | C33: 0.25011983 | D33: 7.8098243 | E33: =C33*Standardisation_Parameters!$F$12+Standardisation_Parameters!$E$12 -> 7.5080154 | F33: 9999999999 | G33: 79 | H33: 0.21491003 | J33: 6 | K33: 0.2347 | L33: =K33*Standardisation_Parameters!$F$12+Standardisation_Parameters!$E$12 -> 7.4254222 | M33: 6 | Q33: (-0.07 : 0.2] | R33: 3 | S33: 0.36138656 | T33: 0.55006107 | U33: =S33*Standardisation_Parameters!$F$6+Standardisation_Parameters!$E$6 -> 14.460048 | V33: =T33*Standardisation_Parameters!$F$6+Standardisation_Parameters!$E$6 -> 15.866048 | W33: 53 | X33: 0.77136815 | Z33: 4 | AA33: 0.7844 | AB33: =AA33*Standardisation_Parameters!$F$6+Standardisation_Parameters!$E$6 -> 17.612338 | AC33: 4
R34: 4 | S34: 0.56522481 | T34: 1.0390582 | U34: =S34*Standardisation_Parameters!$F$6+Standardisation_Parameters!$E$6 -> 15.979048 | V34: =T34*Standardisation_Parameters!$F$6+Standardisation_Parameters!$E$6 -> 19.510048 | W34: 53 | X34: 0.78589454 | Z34: 5 | AA34: 0.8856 | AB34: =AA34*Standardisation_Parameters!$F$6+Standardisation_Parameters!$E$6 -> 18.36648 | AC34: 5
R35: 5 | S35: 1.0402659 | T35: 7.1960739 | U35: =S35*Standardisation_Parameters!$F$6+Standardisation_Parameters!$E$6 -> 19.519048 | V35: 9999999999 | W35: 53 | X35: 1.0976712 | Z35: 6 | AA35: 0.9868 | AB35: =AA35*Standardisation_Parameters!$F$6+Standardisation_Parameters!$E$6 -> 19.120621 | AC35: 6
A36: Buckets | B36: DT | C36: Min | D36: Max | G36: Frequency | H36: Average EIU | J36: Category Num | K36: EIU Fitted | M36: Category Num | N36: Peer Avg
A37: <= -0.41 | B37: 0 | C37: -1.5071845 | D37: -0.47081864 | E37: -9999999999 | F37: =D37*Standardisation_Parameters!$F$13+Standardisation_Parameters!$E$13 -> -16.855192 | G37: 79 | H37: 0.013801017 | J37: 1 | K37: -0.1792 | L37: =K37*Standardisation_Parameters!$F$13+Standardisation_Parameters!$E$13 -> -5.6827061 | M37: 1 | N37: -0.73370412 | O37: =N37*Standardisation_Parameters!$F$13+Standardisation_Parameters!$E$13 -> -26.926855
A38: (-0.41 : -0.1] | B38: 1 | C38: -0.47033545 | D38: -0.16055253 | E38: =C38*Standardisation_Parameters!$F$13+Standardisation_Parameters!$E$13 -> -16.836681 | F38: =D38*Standardisation_Parameters!$F$13+Standardisation_Parameters!$E$13 -> -4.9682848 | G38: 79 | H38: -0.36685598 | J38: 2 | K38: -0.3033 | L38: =K38*Standardisation_Parameters!$F$13+Standardisation_Parameters!$E$13 -> -10.437222 | M38: 2 | N38: -0.29970547 | O38: =N38*Standardisation_Parameters!$F$13+Standardisation_Parameters!$E$13 -> -10.299509 | Q38: Buckets | R38: DSR_5yr | S38: Min | T38: Max | W38: Frequency | X38: Average EIU | Z38: Category Num | AA38: EIU Fitted | AC38: Category Num
A39: (-0.1 : 0.11] | B39: 2 | C39: -0.15983084 | D39: 0.070269783 | E39: =C39*Standardisation_Parameters!$F$13+Standardisation_Parameters!$E$13 -> -4.9406352 | F39: =D39*Standardisation_Parameters!$F$13+Standardisation_Parameters!$E$13 -> 3.8749742 | G39: 80 | H39: -0.53395164 | J39: 3 | K39: -0.4274 | L39: =K39*Standardisation_Parameters!$F$13+Standardisation_Parameters!$E$13 -> -15.191739 | M39: 3 | N39: -0.040468842 | O39: =N39*Standardisation_Parameters!$F$13+Standardisation_Parameters!$E$13 -> -0.3676413 | R39: 0 | S39: -0.95346184 | T39: -0.69391433 | U39: -9999999999 | V39: =T39*Standardisation_Parameters!$F$8+Standardisation_Parameters!$E$8 -> 2.8594226 | W39: 53 | X39: 0.69159345 | Z39: 1 | AA39: 0.6499 | AB39: =AA39*Standardisation_Parameters!$F$8+Standardisation_Parameters!$E$8 -> 17.061416 | AC39: 1
A40: (0.11 : 0.37] | B40: 3 | C40: 0.07291973 | D40: 0.33716897 | E40: =C40*Standardisation_Parameters!$F$13+Standardisation_Parameters!$E$13 -> 3.9764989 | F40: =D40*Standardisation_Parameters!$F$13+Standardisation_Parameters!$E$13 -> 14.10041 | G40: 79 | H40: -0.64697529 | J40: 4 | K40: -0.5515 | L40: =K40*Standardisation_Parameters!$F$13+Standardisation_Parameters!$E$13 -> -19.946255 | M40: 4 | N40: 0.2103889 | O40: =N40*Standardisation_Parameters!$F$13+Standardisation_Parameters!$E$13 -> 9.2432146 | R40: 1 | S40: -0.6884452 | T40: -0.48760154 | U40: =S40*Standardisation_Parameters!$F$8+Standardisation_Parameters!$E$8 -> 2.9172226 | V40: =T40*Standardisation_Parameters!$F$8+Standardisation_Parameters!$E$8 -> 5.0398227 | W40: 53 | X40: 0.59273327 | Z40: 2 | AA40: 0.6646 | AB40: =AA40*Standardisation_Parameters!$F$8+Standardisation_Parameters!$E$8 -> 17.216771 | AC40: 2
...

Sheet Low_Raw
A1: RAW 2011 DATA | B1: country | C1: em_dm | D1: iso_code | E1: dcpi_2011 | F1: dcpi_2009_2011 | G1: dcpi_2007_2011 | H1: rir_2011 | I1: rir_vol_2010_2011 | J1: xcs_2011 | K1: xcm_2011 | L1: growth_vol_2010_2011 | M1: real_gdp_2011 | N1: gdp_capita_2011 | O1: currency_vol_2011 | P1: atf_2011 | Q1: ic_2011 | R1: liq_2011 | S1: cab_2011 | T1: cab_fdi_2011 | U1: fdg_2011 | V1: dsr_2011 | W1: dt_2011 | X1: reer_2011 | Y1: fi_2011 | Z1: cof_2011 | AA1: pr_2011 | AB1: hdi_2011 | AC1: va_2011 | AD1: rol_2011 | AE1: db_2011 | AF1: gci_2011 | AG1: or_2011 | AH1: lr_2011 | AI1: sr_2011 | AJ1: dcpi_3yr_vol_2011 | AK1: dcpi_5yr_vol_2011 | AL1: nom_rir_2011 | AM1: nom_rir_vol_2011 | AN1: growth_vol_sh_2011 | AO1: ic_rc_2011 | AP1: liq_rc_2011 | AQ1: rc_2011 | AR1: rir_rir_vol_2011 | AS1: nir_nir_vol_2011 | AT1: growth_vol_gdp_capita_2011 | AU1: avg_cof_2011 | AV1: currency_vol_adj_2011 | AW1: liq_fx_adj_2011 | AX1: ddi_2011 | AY1: currency_vol_quart_2011 | AZ1: fdg_3year_2011 | BA1: fdg_5year_2011 | BB1: dsr_3year_2011 | BC1: dsr_5year_2011 | BD1: dt_5year_2011 | BE1: ic_rc_3year_2011 | BF1: ic_rc_5year_2011 | BG1: real_gdp_3year_2011 | BH1: real_gdp_5year_2011 | BI1: real_gdp_growth_1year_2011 | BJ1: real_gdp_growth_2year_2011 | BK1: real_gdp_growth_3year_2011 | BL1: real_gdp_growth_5year_2011 | BM1: macro_2011 | BN1: cab_3year_2011 | BO1: cab_actual_2011 | BP1: cab_actual_3year_2011 | BQ1: cab_change_2011 | BR1: cab_liq_rc_2011 | BS1: legal2011 | BT1: tax2011 | BU1: infra2011 | BV1: avgrol2011 | BW1: year | BX1: STD 2011 DATA | BY1: DB | BZ1: Quant | CA1: Qual | CB1: Full without Restriction | CC1: Full with Restriction | CD1: EIU | CF1: country | CG1: em_dm | CH1: iso_code | CI1: yhat_QUANT | CJ1: yhat_qualitative | CK1: eiu_score_std | CL1: yhat_Full1 | CM1: Y_Hat (AFTER) | CN1: db | CP1: country | CQ1: em_dm | CR1: iso_code | CT1: Row Num | CU1: Quant Score | CV1: Qual Score | CW1: EIU_Score | CX1: Fitted Score | CY1: Unstandardised EIU | CZ1: Unstandardised Fitted | DA1: Unstandardised Quant | DB1: Unstandardised Qual
B2: AFGHANISTAN | C2: LOW HUMAN DEVELOPMENT | D2: AFG | F2: -3.6985 | G2: 7.9105 | I2: 16.820837 | L2: 8.6707703 | P2: 3 | Q2: 7.3297637 | U2: 13.459759 | W2: -24.363053 | Y2: 3.8190928 | AA2: 7 | AB2: 0.398 | AC2: -1.4545945 | AD2: -1.8976236 | AE2: 84.153005 | AG2: 4.5 | AH2: 4 | AI2: 4.75 | AM2: 1.4924093 | AN2: 1.469189 | AO2: 21.989291 | AQ2: 3 | AR2: 163.46489 | AS2: 27.151403 | AX2: 0 | AY2: 2.0538148 | AZ2: 15.211538 | BA2: 16.721439 | BD2: -0.34318934 | BE2: 18.994713 | BF2: 16.477656 | BG2: 20.867 | BH2: 12.739 | BJ2: 5.367 | BK2: 11.6545 | BL2: 8.85375 | BM2: 9 | BS2: 83 | BT2: 38 | BU2: 84 | BV2: 68.333333 | BW2: 2011 | BY2: =(AE2-Standardisation_Parameters!$E$15)/Standardisation_Parameters!$F$15 -> 1.4515918 | BZ2: =VLOOKUP($D2,$CH:$CN,2,FALSE) -> #N/A | CA2: =VLOOKUP($D2,$CH:$CN,3,FALSE) -> #N/A | CB2: =VLOOKUP($D2,$CH:$CN,5,FALSE) -> #N/A | CC2: =VLOOKUP($D2,$CH:$CN,6,FALSE) -> #N/A | CD2: =VLOOKUP($D2,$CH:$CN,4,FALSE) -> #N/A | CF2: ANGOLA | CG2: LOW HUMAN DEVELOPMENT | CH2: AGO | CI2: 1.0000433 | CJ2: 1.2666655 | CK2: 0.61131204 | CL2: 1.2612366 | CM2: 1.2017588 | CN2: 1.0054 | CP2: ANGOLA | CQ2: LOW HUMAN DEVELOPMENT | CR2: AGO | CS2: AGO2011 | CT2: 7 | CU2: 1.0000433 | CV2: 1.2666655 | CW2: 0.61131204 | CX2: 1.2017545 | CY2: 54.888889 | CZ2: 64.758165 | DA2: 61.38655 | DB2: 65.843154
B3: ALGERIA | C3: MEDIUM HUMAN DEVELOPMENT | D3: DZA | E3: 4.531 | F3: 4.7276667 | G3: 4.8714 | H3: 3.469 | I3: 1.3044918 | J3: 98.303 | K3: 24.225 | L3: 0.42778499 | M3: 2.5 | N3: 5680 | O3: 3.9295193 | P3: 1 | Q3: 36.7 | R3: 0.89563399 | S3: 8.9 | T3: 10.291363 | U3: 1.9147501 | V3: 1.7 | W3: -51.241651 | X3: 3.113 | Y3: -7.4197348 | Z3: 1.06 | AA3: 5 | AB3: 0.698 | AC3: -1.0087942 | AD3: -0.75892415 | AE3: 78.142077 | AF3: 3.9584222 | AG3: 3.5 | AH3: 3 | AI3: 3.5 | AJ3: -0.19666667 | AK3: -1.2714 | AL3: 8 | AM3: 0 | AN3: 6.4050868 | AO3: 110.1 | AP3: 2.686902 | AQ3: 3 | AR3: 5.8428187 | AS3: 0 | AT3: 1180.4 | AU3: 0.18211576 | AV3: 5.2610142 | AW3: -0.99104366 | AX3: 10 | AY3: 3.8803788 | AZ3: 3.0328998 | BA3: 3.385049 | BB3: 1.9666667 | BC3: 1.1918 | BD3: -0.56189926 | BE3: 111.706 | BF3: 112.0188 | BG3: 2.7333333 | BH3: 2.74 | BI3: 1.7 | BJ3: 1.5 | BK3: 1.2333333 | BL3: 1.1156 | BM3: 5 | BN3: 5.568 | BO3: 8.9 | BP3: 5.568 | BQ3: 0.2501796 | BR3: 0.17345127 | BS3: 80 | BT3: 69 | BU3: 69 | BV3: 72.666667 | BW3: 2011 | BY3: =(AE3-Standardisation_Parameters!$E$15)/Standardisation_Parameters!$F$15 -> 1.2341468 | BZ3: =VLOOKUP($D3,$CH:$CN,2,FALSE) -> 0.31284052 | CA3: =VLOOKUP($D3,$CH:$CN,3,FALSE) -> 0.83406275 | CB3: =VLOOKUP($D3,$CH:$CN,5,FALSE) -> 0.68928127 | CC3: =VLOOKUP($D3,$CH:$CN,6,FALSE) -> 0.50387547 | CD3: =VLOOKUP($D3,$CH:$CN,4,FALSE) -> 1.0566858 | CF3: BURKINA FASO | CG3: LOW HUMAN DEVELOPMENT | CH3: BFA | CI3: 0.25120715 | CJ3: 0.51701512 | CK3: 0.35206462 | CL3: 0.40499109 | CM3: 0.29076185 | CN3: 0.8966 | CP3: BURKINA FASO | CQ3: LOW HUMAN DEVELOPMENT | CR3: BFA | CS3: BFA2011 | CT3: 12 | CU3: 0.25120715 | CV3: 0.51701512 | CW3: 0.35206462 | CX3: 0.29075932 | CY3: 50.555556 | CZ3: 49.530834 | DA3: 48.869718 | DB3: 53.312711
B4: ANGOLA | C4: LOW HUMAN DEVELOPMENT | D4: AGO | E4: 13.465 | F4: 13.945 | G4: 13.3116 | H4: 3.535 | I4: 3.1412234 | J4: 96.624 | K4: 43.063 | L4: 8.4735089 | M4: 3.4 | N4: 5330 | O4: 8.8121997 | P4: 3 | Q4: 7.7 | R4: 11.54617 | S4: 13.2 | T4: 24.034578 | U4: 17.360197 | V4: 8.9 | W4: -21.126399 | X4: -0.4 | Y4: 22.865688 | AA4: 5 | AB4: 0.486 | AC4: -1.1392457 | AD4: -1.2437801 | AE4: 93.442623 | AF4: 2.9614977 | AG4: 3.25 | AH4: 3.25 | AI4: 3.5 | AJ4: -0.48 | AK4: -2.0116 | AL4: 17 | AM4: 3.6504 | AN4: 0.9725841 | AO4: 23.1 | AP4: 34.638511 | AQ4: 3 | AR4: 17.122809 | AS4: 64.61208 | AT4: 1010 | AV4: 22.204027 | AW4: -0.8845383 | AX4: 0 | AY4: 8.3976008 | AZ4: 20.62602 | BA4: 19.841876 | BB4: 7.3666667 | BC4: 6.88 | BD4: -0.104812 | BE4: 18.311 | BF4: 17.0352 | BG4: 2.5206667 | BH4: 8.2412 | BI4: 0.5 | BJ4: 0.5 | BK4: -0.349 | BL4: 5.1674 | BM4: 7 | BN4: 4.056 | BO4: 13.2 | BP4: 4.056 | BQ4: 1.0359961 | BR4: 1.797397 | BS4: 75 | BT4: 38 | BU4: 72 | BV4: 61.666667 | BW4: 2011 | BY4: =(AE4-Standardisation_Parameters!$E$15)/Standardisation_Parameters!$F$15 -> 1.787643 | BZ4: =VLOOKUP($D4,$CH:$CN,2,FALSE) -> 1.0000433 | CA4: =VLOOKUP($D4,$CH:$CN,3,FALSE) -> 1.2666655 | CB4: =VLOOKUP($D4,$CH:$CN,5,FALSE) -> 1.2612366 | CC4: =VLOOKUP($D4,$CH:$CN,6,FALSE) -> 1.2017588 | CD4: =VLOOKUP($D4,$CH:$CN,4,FALSE) -> 0.61131204 | CF4: BANGLADESH | CG4: LOW HUMAN DEVELOPMENT | CH4: BGD | CI4: 0.81968458 | CJ4: 0.74080165 | CK4: 0.64454888 | CL4: 0.76586176 | CM4: 0.79554383 | CN4: 0.679 | CP4: BANGLADESH | CQ4: LOW HUMAN DEVELOPMENT | CR4: BGD | CS4: BGD2011 | CT4: 18 | CU4: 0.81968458 | CV4: 0.74080165 | CW4: 0.64454888 | CX4: 0.79554116 | CY4: 55.444444 | CZ4: 57.968288 | DA4: 58.371846 | DB4: 57.053314
B5: BANGLADESH | C5: LOW HUMAN DEVELOPMENT | D5: BGD | E5: 10.706 | F5: 8.0853333 | G5: 8.453 | H5: 2.294 | I5: 2.6446919 | J5: 65.834 | K5: 22.142 | L5: 0.35062444 | M5: 6.662 | N5: 649 | O5: 2.3183851 | P5: 3 | Q5: 3 | R5: 35.06669 | S5: 0.4 | T5: 1.4145141 | U5: 23.391782 | V5: 3.4 | W5: -12.178117 | X5: -0.4 | Y5: 65.941996 | Z5: 5 | AA5: 3 | AB5: 0.5 | AC5: -0.27560594 | AD5: -0.76846154 | AE5: 64.480874 | AF5: 3.7308962 | AG5: 3.5 | AH5: 3.25 | AI5: 3.75 | AJ5: 2.6206667 | AK5: 1.647 | AL5: 13 | AM5: 1.6006499 | AN5: 17.734075 | AO5: 9 | AP5: 105.20007 | AQ5: 3 | AR5: 18.229862 | AS5: 25.610398 | AT5: 40.3 | AU5: 0.85903661 | AV5: 7.6624431 | AW5: -0.6493331 | AX5: 0 | AY5: 2.35902 | AZ5: 24.989638 | BA5: 26.963199 | BB5: 3.345 | BC5: 3.6728 | BD5: 1.3441242 | BE5: 12.992 | BF5: 11.3946 | BG5: 6.1573333 | BH5: 6.218 | BI5: 16.542 | BJ5: 10.593 | BK5: 8.4933333 | BL5: 7.012 | BM5: 7 | BN5: 2.2933333 | BO5: 0.4 | BP5: 2.2933333 | BQ5: -0.91569767 | BR5: 1.1930196 | BS5: 68 | BT5: 38 | BU5: 81 | BV5: 62.333333 | BW5: 2011 | BY5: =(AE5-Standardisation_Parameters!$E$15)/Standardisation_Parameters!$F$15 -> 0.73995372 | BZ5: =VLOOKUP($D5,$CH:$CN,2,FALSE) -> 0.81968458 | CA5: =VLOOKUP($D5,$CH:$CN,3,FALSE) -> 0.74080165 | CB5: =VLOOKUP($D5,$CH:$CN,5,FALSE) -> 0.76586176 | CC5: =VLOOKUP($D5,$CH:$CN,6,FALSE) -> 0.79554383 | CD5: =VLOOKUP($D5,$CH:$CN,4,FALSE) -> 0.64454888 | CF5: BOLIVIA, PLURINATIONAL STATE OF | CG5: MEDIUM HUMAN DEVELOPMENT | CH5: BOL | CI5: 0.91507548 | CJ5: 1.1625483 | CK5: 1.22287 | CL5: 1.148124 | CM5: 1.0880821 | CN5: 0.8966 | CP5: BOLIVIA, PLURINATIONAL STATE OF | CQ5: MEDIUM HUMAN DEVELOPMENT | CR5: BOL | CS5: BOL2011 | CT5: 24 | CU5: 0.91507548 | CV5: 1.1625483 | CW5: 1.22287 | CX5: 1.0880781 | CY5: 65.111111 | CZ5: 62.858057 | DA5: 59.96631 | DB5: 64.102831
B6: BOLIVIA, PLURINATIONAL STATE OF | C6: MEDIUM HUMAN DEVELOPMENT | D6: BOL | E6: 9.883 | F6: 5.2436667 | G6: 7.6888 | H6: 1.017 | I6: 3.9485443 | J6: 14.103 | K6: 42.367 | L6: 1.021486 | M6: 4.4 | N6: 2220 | O6: 0.35199552 | P6: 3 | Q6: 17.6 | R6: 1.3984885 | S6: 4.1 | T6: 6.9101992 | U6: 25.961836 | V6: 4.8 | W6: -23.063166 | X6: 4.676 | Y6: 49.371658 | Z6: 1.8 | AA6: 6 | AB6: 0.663 | AC6: -0.088978093 | AD6: -1.0649306 | AE6: 80.327869 | AF6: 3.8158868 | AG6: 4 | AH6: 4.25 | AI6: 3.25 | AJ6: 4.6393333 | AK6: -3.1888 | AL6: 10.9 | AM6: 1.5772734 | AN6: 4.4241428 | AO6: 52.8 | AP6: 4.1954655 | AQ6: 3 | AR6: 16.414098 | AS6: 20.285314 | AT6: 275.5 | AU6: 0.30925318 | AV6: -11.001342 | AW6: -0.98601511 | AX6: 3 | AY6: 0.33870193 | AZ6: 29.017893 | BA6: 31.672397 | BB6: 7.669 | BC6: 9.1058 | BD6: 1.6782946 | BE6: 56.232 | BF6: 52.5978 | BG6: 3.9613333 | BH6: 4.5192 | BI6: 3.506 | BJ6: 2.9775 | BK6: 2.575 | BL6: 3.0028 | BM6: 7 | BN6: 4.532 | BO6: 4.1 | BP6: 4.532 | BQ6: -0.14805825 | BR6: 1.2830375 | BS6: 75 | BT6: 63 | BU6: 75 | BV6: 71 | BW6: 2011 | BY6: =(AE6-Standardisation_Parameters!$E$15)/Standardisation_Parameters!$F$15 -> 1.3132177 | BZ6: =VLOOKUP($D6,$CH:$CN,2,FALSE) -> 0.91507548 | CA6: =VLOOKUP($D6,$CH:$CN,3,FALSE) -> 1.1625483 | CB6: =VLOOKUP($D6,$CH:$CN,5,FALSE) -> 1.148124 | CC6: =VLOOKUP($D6,$CH:$CN,6,FALSE) -> 1.0880821 | CD6: =VLOOKUP($D6,$CH:$CN,4,FALSE) -> 1.22287 | CF6: BOTSWANA | CG6: MEDIUM HUMAN DEVELOPMENT | CH6: BWA | CI6: 0.10257794 | CJ6: -0.23900037 | CK6: -0.53868291 | CL6: -0.27341966 | CM6: -0.21853939 | CN6: 0.4614 | CP6: BOTSWANA | CQ6: MEDIUM HUMAN DEVELOPMENT | CR6: BWA | CS6: BWA2011 | CT6: 30 | CU6: 0.10257794 | CV6: -0.23900037 | CW6: -0.53868291 | CX6: -0.21853953 | CY6: 35.666667 | CZ6: 41.017879 | DA6: 46.385373 | DB6: 40.675875
B7: BOTSWANA | C7: MEDIUM HUMAN DEVELOPMENT | D7: BWA | E7: 8.5 | F7: 7.856 | G7: 8.6532 | H7: 2.5 | I7: 2.5058413 | J7: 69.8 | K7: 55.275 | L7: 4.7294234 | M7: 5.4 | N7: 8450 | O7: 0.36897065 | P7: 1 | Q7: 13.5 | R7: 5.5360353 | S7: -2.8 | T7: -0.92586023 | U7: 11.663119 | V7: 2.1 | W7: -17.257694 | X7: 14.9 | Y7: 9.3515395 | Z7: 9.5 | AA7: 3 | AB7: 0.633 | AC7: 0.43229165 | AD7: 0.66341102 | AE7: 28.415301 | AF7: 4.0470745 | AG7: 2 | AH7: 2.25 | AI7: 1.5 | AJ7: 0.644 | AK7: -2.3532 | AL7: 11 | AM7: 2.5826885 | AN7: 0.64798597 | AO7: 40.5 | AP7: 16.608106 | AQ7: 3 | AR7: 22.905895 | AS7: 41.891208 | AT7: 936.9 | AU7: 1.6321696 | AV7: 9.0604027 | AW7: -0.94463965 | AX7: 3 | AY7: 0.52256681 | AZ7: 12.419635 | BA7: 8.7632766 | BB7: 2.1186667 | BC7: 1.6382 | BD7: -0.18565311 | BE7: 50.622 | BF7: 58.842 | BG7: 2.5543333 | BH7: 3.0646 | BI7: 3.8 | BJ7: 4.662 | BK7: 1.0113333 | BL7: 1.613 | BM7: 3 | BN7: -4.2013333 | BO7: -2.8 | BP7: -4.2013333 | BQ7: -0.5407807 | BR7: -0.82102777 | BS7: 40 | BT7: 25 | BU7: 38 | BV7: 34.333333 | BW7: 2011 | BY7: =(AE7-Standardisation_Parameters!$E$15)/Standardisation_Parameters!$F$15 -> -0.56471601 | BZ7: =VLOOKUP($D7,$CH:$CN,2,FALSE) -> 0.10257794 | CA7: =VLOOKUP($D7,$CH:$CN,3,FALSE) -> -0.23900037 | CB7: =VLOOKUP($D7,$CH:$CN,5,FALSE) -> -0.27341966 | CC7: =VLOOKUP($D7,$CH:$CN,6,FALSE) -> -0.21853939 | CD7: =VLOOKUP($D7,$CH:$CN,4,FALSE) -> -0.53868291 | CF7: CENTRAL AFRICAN REPUBLIC | CG7: LOW HUMAN DEVELOPMENT | CH7: CAF | CI7: 0.95445381 | CJ7: 1.446723 | CK7: 1.0367437 | CL7: 1.3980963 | CM7: 1.2683905 | CN7: 1.0054 | CP7: CENTRAL AFRICAN REPUBLIC | CQ7: LOW HUMAN DEVELOPMENT | CR7: CAF | CS7: CAF2011 | CT7: 33 | CU7: 0.95445381 | CV7: 1.446723 | CW7: 1.0367437 | CX7: 1.2683856 | CY7: 62 | CZ7: 65.871906 | DA7: 60.624521 | DB7: 68.852825
B8: BURKINA FASO | C8: LOW HUMAN DEVELOPMENT | D8: BFA | E8: 2.7 | F8: 1.5146667 | G8: 2.9946 | K8: 7.769 | L8: 1.8687568 | M8: 5.6 | N8: 597 | O8: 17.115318 | P8: 3 | Q8: 4.5 | R8: 4.4264078 | S8: -3.5 | U8: 22.680158 | V8: 3.3 | W8: 15.816991 | X8: -1.5 | Y8: 16.442008 | Z8: 3.3 | AA8: 5 | AB8: 0.331 | AC8: -0.24020444 | AD8: -0.21392659 | AE8: 82.513661 | AF8: 3.2529644 | AG8: 3.75 | AH8: 3.25 | AI8: 3 | AJ8: 1.1853333 | AK8: 0.0054 | AN8: 2.7287661 | AO8: 13.5 | AP8: 13.279223 | AQ8: 3 | AT8: 43 | AU8: 0.56696416 | AV8: -1.5440256 | AW8: -0.95573592 | AX8: 1 | AY8: 26.341653 | AZ8: 21.383601 | BA8: 20.470982 | BB8: 3.7 | BC8: 3.96 | BD8: -0.24944125 | BE8: 17.8 | BF8: 17.8548 | BG8: 5.5666667 | BH8: 5.0994 | BI8: 1.1 | BJ8: 2.9 | BK8: 1.9 | BL8: 1.798 | BM8: 4 | BN8: -3.854 | BO8: -3.5 | BP8: -3.854 | BQ8: -0.032693306 | BR8: -8.6530834 | BS8: 63 | BT8: 25 | BU8: 69 | BV8: 52.333333 | BW8: 2011 | BY8: =(AE8-Standardisation_Parameters!$E$15)/Standardisation_Parameters!$F$15 -> 1.3922886 | BZ8: =VLOOKUP($D8,$CH:$CN,2,FALSE) -> 0.25120715 | CA8: =VLOOKUP($D8,$CH:$CN,3,FALSE) -> 0.51701512 | CB8: =VLOOKUP($D8,$CH:$CN,5,FALSE) -> 0.40499109 | CC8: =VLOOKUP($D8,$CH:$CN,6,FALSE) -> 0.29076185 | CD8: =VLOOKUP($D8,$CH:$CN,4,FALSE) -> 0.35206462 | CF8: CHINA | CG8: MEDIUM HUMAN DEVELOPMENT | CH8: CHN | CI8: -0.060995903 | CJ8: 0.47600229 | CK8: 0.21911723 | CL8: 0.27537403 | CM8: 0.057838697 | CN8: 0.5702 | CP8: CHINA | CQ8: MEDIUM HUMAN DEVELOPMENT | CR8: CHN | CS8: CHN2011 | CT8: 39 | CU8: -0.060995903 | CV8: 0.47600229 | CW8: 0.21911723 | CX8: 0.057835966 | CY8: 48.333333 | CZ8: 45.637509 | DA8: 43.651229 | DB8: 52.62718
